2024-10-05 03:24:14,409 - INFO - Stategy_Fibo copy.py - 404 - Starting value: 6321.14
2024-10-05 03:24:14,411 - INFO - Stategy_Fibo copy.py - 405 - Target amount: 10000
2024-10-05 03:24:14,411 - INFO - Stategy_Fibo copy.py - 406 - Betted On,CurrentValue,TargetAmt,Losscount,Wincount
2024-10-05 03:24:14,742 - ERROR - Stategy_Fibo copy.py - 469 - An error occurred in the connection function: 
Traceback (most recent call last):
  File "C:\Users\Umesh Patel\AppData\Local\Programs\Python\Python312\Lib\site-packages\pyautogui\__init__.py", line 172, in wrapper
    return wrappedFunction(*args, **kwargs)
           ^^^^^^^^^^^^^^^^^^^^^^^^^^^^^^^^
  File "C:\Users\Umesh Patel\AppData\Local\Programs\Python\Python312\Lib\site-packages\pyautogui\__init__.py", line 210, in locateOnScreen
    return pyscreeze.locateOnScreen(*args, **kwargs)
           ^^^^^^^^^^^^^^^^^^^^^^^^^^^^^^^^^^^^^^^^^
  File "C:\Users\Umesh Patel\AppData\Local\Programs\Python\Python312\Lib\site-packages\pyscreeze\__init__.py", line 405, in locateOnScreen
    retVal = locate(image, screenshotIm, **kwargs)
             ^^^^^^^^^^^^^^^^^^^^^^^^^^^^^^^^^^^^^
  File "C:\Users\Umesh Patel\AppData\Local\Programs\Python\Python312\Lib\site-packages\pyscreeze\__init__.py", line 383, in locate
    points = tuple(locateAll(needleImage, haystackImage, **kwargs))
             ^^^^^^^^^^^^^^^^^^^^^^^^^^^^^^^^^^^^^^^^^^^^^^^^^^^^^^
  File "C:\Users\Umesh Patel\AppData\Local\Programs\Python\Python312\Lib\site-packages\pyscreeze\__init__.py", line 257, in _locateAll_opencv
    raise ImageNotFoundException('Could not locate the image (highest confidence = %.3f)' % result.max())
pyscreeze.ImageNotFoundException: Could not locate the image (highest confidence = 0.580)

During handling of the above exception, another exception occurred:

Traceback (most recent call last):
  File "c:\Users\Umesh Patel\Omnitrix\Stategy_Fibo copy.py", line 461, in <module>
    connection_check = pyautogui.locateOnScreen("Connnection.png", confidence=0.8)
                       ^^^^^^^^^^^^^^^^^^^^^^^^^^^^^^^^^^^^^^^^^^^^^^^^^^^^^^^^^^^
  File "C:\Users\Umesh Patel\AppData\Local\Programs\Python\Python312\Lib\site-packages\pyautogui\__init__.py", line 174, in wrapper
    raise ImageNotFoundException  # Raise PyAutoGUI's ImageNotFoundException.
    ^^^^^^^^^^^^^^^^^^^^^^^^^^^^
pyautogui.ImageNotFoundException
2024-10-05 03:24:23,480 - INFO - Stategy_Fibo copy.py - 296 - B,6321.14,10000,0,0
2024-10-05 03:24:26,855 - INFO - Stategy_Fibo copy.py - 798 - Checking Bet history []
2024-10-05 03:24:52,534 - ERROR - Stategy_Fibo copy.py - 469 - An error occurred in the connection function: 
Traceback (most recent call last):
  File "C:\Users\Umesh Patel\AppData\Local\Programs\Python\Python312\Lib\site-packages\pyautogui\__init__.py", line 172, in wrapper
    return wrappedFunction(*args, **kwargs)
           ^^^^^^^^^^^^^^^^^^^^^^^^^^^^^^^^
  File "C:\Users\Umesh Patel\AppData\Local\Programs\Python\Python312\Lib\site-packages\pyautogui\__init__.py", line 210, in locateOnScreen
    return pyscreeze.locateOnScreen(*args, **kwargs)
           ^^^^^^^^^^^^^^^^^^^^^^^^^^^^^^^^^^^^^^^^^
  File "C:\Users\Umesh Patel\AppData\Local\Programs\Python\Python312\Lib\site-packages\pyscreeze\__init__.py", line 405, in locateOnScreen
    retVal = locate(image, screenshotIm, **kwargs)
             ^^^^^^^^^^^^^^^^^^^^^^^^^^^^^^^^^^^^^
  File "C:\Users\Umesh Patel\AppData\Local\Programs\Python\Python312\Lib\site-packages\pyscreeze\__init__.py", line 383, in locate
    points = tuple(locateAll(needleImage, haystackImage, **kwargs))
             ^^^^^^^^^^^^^^^^^^^^^^^^^^^^^^^^^^^^^^^^^^^^^^^^^^^^^^
  File "C:\Users\Umesh Patel\AppData\Local\Programs\Python\Python312\Lib\site-packages\pyscreeze\__init__.py", line 257, in _locateAll_opencv
    raise ImageNotFoundException('Could not locate the image (highest confidence = %.3f)' % result.max())
pyscreeze.ImageNotFoundException: Could not locate the image (highest confidence = 0.580)

During handling of the above exception, another exception occurred:

Traceback (most recent call last):
  File "c:\Users\Umesh Patel\Omnitrix\Stategy_Fibo copy.py", line 461, in <module>
    connection_check = pyautogui.locateOnScreen("Connnection.png", confidence=0.8)
                       ^^^^^^^^^^^^^^^^^^^^^^^^^^^^^^^^^^^^^^^^^^^^^^^^^^^^^^^^^^^
  File "C:\Users\Umesh Patel\AppData\Local\Programs\Python\Python312\Lib\site-packages\pyautogui\__init__.py", line 174, in wrapper
    raise ImageNotFoundException  # Raise PyAutoGUI's ImageNotFoundException.
    ^^^^^^^^^^^^^^^^^^^^^^^^^^^^
pyautogui.ImageNotFoundException
2024-10-05 03:24:55,458 - ERROR - Stategy_Fibo copy.py - 469 - An error occurred in the connection function: 
Traceback (most recent call last):
  File "C:\Users\Umesh Patel\AppData\Local\Programs\Python\Python312\Lib\site-packages\pyautogui\__init__.py", line 172, in wrapper
    return wrappedFunction(*args, **kwargs)
           ^^^^^^^^^^^^^^^^^^^^^^^^^^^^^^^^
  File "C:\Users\Umesh Patel\AppData\Local\Programs\Python\Python312\Lib\site-packages\pyautogui\__init__.py", line 210, in locateOnScreen
    return pyscreeze.locateOnScreen(*args, **kwargs)
           ^^^^^^^^^^^^^^^^^^^^^^^^^^^^^^^^^^^^^^^^^
  File "C:\Users\Umesh Patel\AppData\Local\Programs\Python\Python312\Lib\site-packages\pyscreeze\__init__.py", line 405, in locateOnScreen
    retVal = locate(image, screenshotIm, **kwargs)
             ^^^^^^^^^^^^^^^^^^^^^^^^^^^^^^^^^^^^^
  File "C:\Users\Umesh Patel\AppData\Local\Programs\Python\Python312\Lib\site-packages\pyscreeze\__init__.py", line 383, in locate
    points = tuple(locateAll(needleImage, haystackImage, **kwargs))
             ^^^^^^^^^^^^^^^^^^^^^^^^^^^^^^^^^^^^^^^^^^^^^^^^^^^^^^
  File "C:\Users\Umesh Patel\AppData\Local\Programs\Python\Python312\Lib\site-packages\pyscreeze\__init__.py", line 257, in _locateAll_opencv
    raise ImageNotFoundException('Could not locate the image (highest confidence = %.3f)' % result.max())
pyscreeze.ImageNotFoundException: Could not locate the image (highest confidence = 0.580)

During handling of the above exception, another exception occurred:

Traceback (most recent call last):
  File "c:\Users\Umesh Patel\Omnitrix\Stategy_Fibo copy.py", line 461, in <module>
    connection_check = pyautogui.locateOnScreen("Connnection.png", confidence=0.8)
                       ^^^^^^^^^^^^^^^^^^^^^^^^^^^^^^^^^^^^^^^^^^^^^^^^^^^^^^^^^^^
  File "C:\Users\Umesh Patel\AppData\Local\Programs\Python\Python312\Lib\site-packages\pyautogui\__init__.py", line 174, in wrapper
    raise ImageNotFoundException  # Raise PyAutoGUI's ImageNotFoundException.
    ^^^^^^^^^^^^^^^^^^^^^^^^^^^^
pyautogui.ImageNotFoundException
2024-10-05 03:24:58,431 - ERROR - Stategy_Fibo copy.py - 469 - An error occurred in the connection function: 
Traceback (most recent call last):
  File "C:\Users\Umesh Patel\AppData\Local\Programs\Python\Python312\Lib\site-packages\pyautogui\__init__.py", line 172, in wrapper
    return wrappedFunction(*args, **kwargs)
           ^^^^^^^^^^^^^^^^^^^^^^^^^^^^^^^^
  File "C:\Users\Umesh Patel\AppData\Local\Programs\Python\Python312\Lib\site-packages\pyautogui\__init__.py", line 210, in locateOnScreen
    return pyscreeze.locateOnScreen(*args, **kwargs)
           ^^^^^^^^^^^^^^^^^^^^^^^^^^^^^^^^^^^^^^^^^
  File "C:\Users\Umesh Patel\AppData\Local\Programs\Python\Python312\Lib\site-packages\pyscreeze\__init__.py", line 405, in locateOnScreen
    retVal = locate(image, screenshotIm, **kwargs)
             ^^^^^^^^^^^^^^^^^^^^^^^^^^^^^^^^^^^^^
  File "C:\Users\Umesh Patel\AppData\Local\Programs\Python\Python312\Lib\site-packages\pyscreeze\__init__.py", line 383, in locate
    points = tuple(locateAll(needleImage, haystackImage, **kwargs))
             ^^^^^^^^^^^^^^^^^^^^^^^^^^^^^^^^^^^^^^^^^^^^^^^^^^^^^^
  File "C:\Users\Umesh Patel\AppData\Local\Programs\Python\Python312\Lib\site-packages\pyscreeze\__init__.py", line 257, in _locateAll_opencv
    raise ImageNotFoundException('Could not locate the image (highest confidence = %.3f)' % result.max())
pyscreeze.ImageNotFoundException: Could not locate the image (highest confidence = 0.580)

During handling of the above exception, another exception occurred:

Traceback (most recent call last):
  File "c:\Users\Umesh Patel\Omnitrix\Stategy_Fibo copy.py", line 461, in <module>
    connection_check = pyautogui.locateOnScreen("Connnection.png", confidence=0.8)
                       ^^^^^^^^^^^^^^^^^^^^^^^^^^^^^^^^^^^^^^^^^^^^^^^^^^^^^^^^^^^
  File "C:\Users\Umesh Patel\AppData\Local\Programs\Python\Python312\Lib\site-packages\pyautogui\__init__.py", line 174, in wrapper
    raise ImageNotFoundException  # Raise PyAutoGUI's ImageNotFoundException.
    ^^^^^^^^^^^^^^^^^^^^^^^^^^^^
pyautogui.ImageNotFoundException
2024-10-05 03:25:01,412 - ERROR - Stategy_Fibo copy.py - 469 - An error occurred in the connection function: 
Traceback (most recent call last):
  File "C:\Users\Umesh Patel\AppData\Local\Programs\Python\Python312\Lib\site-packages\pyautogui\__init__.py", line 172, in wrapper
    return wrappedFunction(*args, **kwargs)
           ^^^^^^^^^^^^^^^^^^^^^^^^^^^^^^^^
  File "C:\Users\Umesh Patel\AppData\Local\Programs\Python\Python312\Lib\site-packages\pyautogui\__init__.py", line 210, in locateOnScreen
    return pyscreeze.locateOnScreen(*args, **kwargs)
           ^^^^^^^^^^^^^^^^^^^^^^^^^^^^^^^^^^^^^^^^^
  File "C:\Users\Umesh Patel\AppData\Local\Programs\Python\Python312\Lib\site-packages\pyscreeze\__init__.py", line 405, in locateOnScreen
    retVal = locate(image, screenshotIm, **kwargs)
             ^^^^^^^^^^^^^^^^^^^^^^^^^^^^^^^^^^^^^
  File "C:\Users\Umesh Patel\AppData\Local\Programs\Python\Python312\Lib\site-packages\pyscreeze\__init__.py", line 383, in locate
    points = tuple(locateAll(needleImage, haystackImage, **kwargs))
             ^^^^^^^^^^^^^^^^^^^^^^^^^^^^^^^^^^^^^^^^^^^^^^^^^^^^^^
  File "C:\Users\Umesh Patel\AppData\Local\Programs\Python\Python312\Lib\site-packages\pyscreeze\__init__.py", line 257, in _locateAll_opencv
    raise ImageNotFoundException('Could not locate the image (highest confidence = %.3f)' % result.max())
pyscreeze.ImageNotFoundException: Could not locate the image (highest confidence = 0.580)

During handling of the above exception, another exception occurred:

Traceback (most recent call last):
  File "c:\Users\Umesh Patel\Omnitrix\Stategy_Fibo copy.py", line 461, in <module>
    connection_check = pyautogui.locateOnScreen("Connnection.png", confidence=0.8)
                       ^^^^^^^^^^^^^^^^^^^^^^^^^^^^^^^^^^^^^^^^^^^^^^^^^^^^^^^^^^^
  File "C:\Users\Umesh Patel\AppData\Local\Programs\Python\Python312\Lib\site-packages\pyautogui\__init__.py", line 174, in wrapper
    raise ImageNotFoundException  # Raise PyAutoGUI's ImageNotFoundException.
    ^^^^^^^^^^^^^^^^^^^^^^^^^^^^
pyautogui.ImageNotFoundException
2024-10-05 03:25:08,901 - INFO - Stategy_Fibo copy.py - 296 - B,6271.14,10000,1,0
2024-10-05 03:25:12,277 - INFO - Stategy_Fibo copy.py - 798 - Checking Bet history ['A']
2024-10-05 03:25:37,923 - ERROR - Stategy_Fibo copy.py - 469 - An error occurred in the connection function: 
Traceback (most recent call last):
  File "C:\Users\Umesh Patel\AppData\Local\Programs\Python\Python312\Lib\site-packages\pyautogui\__init__.py", line 172, in wrapper
    return wrappedFunction(*args, **kwargs)
           ^^^^^^^^^^^^^^^^^^^^^^^^^^^^^^^^
  File "C:\Users\Umesh Patel\AppData\Local\Programs\Python\Python312\Lib\site-packages\pyautogui\__init__.py", line 210, in locateOnScreen
    return pyscreeze.locateOnScreen(*args, **kwargs)
           ^^^^^^^^^^^^^^^^^^^^^^^^^^^^^^^^^^^^^^^^^
  File "C:\Users\Umesh Patel\AppData\Local\Programs\Python\Python312\Lib\site-packages\pyscreeze\__init__.py", line 405, in locateOnScreen
    retVal = locate(image, screenshotIm, **kwargs)
             ^^^^^^^^^^^^^^^^^^^^^^^^^^^^^^^^^^^^^
  File "C:\Users\Umesh Patel\AppData\Local\Programs\Python\Python312\Lib\site-packages\pyscreeze\__init__.py", line 383, in locate
    points = tuple(locateAll(needleImage, haystackImage, **kwargs))
             ^^^^^^^^^^^^^^^^^^^^^^^^^^^^^^^^^^^^^^^^^^^^^^^^^^^^^^
  File "C:\Users\Umesh Patel\AppData\Local\Programs\Python\Python312\Lib\site-packages\pyscreeze\__init__.py", line 257, in _locateAll_opencv
    raise ImageNotFoundException('Could not locate the image (highest confidence = %.3f)' % result.max())
pyscreeze.ImageNotFoundException: Could not locate the image (highest confidence = 0.580)

During handling of the above exception, another exception occurred:

Traceback (most recent call last):
  File "c:\Users\Umesh Patel\Omnitrix\Stategy_Fibo copy.py", line 461, in <module>
    connection_check = pyautogui.locateOnScreen("Connnection.png", confidence=0.8)
                       ^^^^^^^^^^^^^^^^^^^^^^^^^^^^^^^^^^^^^^^^^^^^^^^^^^^^^^^^^^^
  File "C:\Users\Umesh Patel\AppData\Local\Programs\Python\Python312\Lib\site-packages\pyautogui\__init__.py", line 174, in wrapper
    raise ImageNotFoundException  # Raise PyAutoGUI's ImageNotFoundException.
    ^^^^^^^^^^^^^^^^^^^^^^^^^^^^
pyautogui.ImageNotFoundException
2024-10-05 03:25:40,649 - ERROR - Stategy_Fibo copy.py - 469 - An error occurred in the connection function: 
Traceback (most recent call last):
  File "C:\Users\Umesh Patel\AppData\Local\Programs\Python\Python312\Lib\site-packages\pyautogui\__init__.py", line 172, in wrapper
    return wrappedFunction(*args, **kwargs)
           ^^^^^^^^^^^^^^^^^^^^^^^^^^^^^^^^
  File "C:\Users\Umesh Patel\AppData\Local\Programs\Python\Python312\Lib\site-packages\pyautogui\__init__.py", line 210, in locateOnScreen
    return pyscreeze.locateOnScreen(*args, **kwargs)
           ^^^^^^^^^^^^^^^^^^^^^^^^^^^^^^^^^^^^^^^^^
  File "C:\Users\Umesh Patel\AppData\Local\Programs\Python\Python312\Lib\site-packages\pyscreeze\__init__.py", line 405, in locateOnScreen
    retVal = locate(image, screenshotIm, **kwargs)
             ^^^^^^^^^^^^^^^^^^^^^^^^^^^^^^^^^^^^^
  File "C:\Users\Umesh Patel\AppData\Local\Programs\Python\Python312\Lib\site-packages\pyscreeze\__init__.py", line 383, in locate
    points = tuple(locateAll(needleImage, haystackImage, **kwargs))
             ^^^^^^^^^^^^^^^^^^^^^^^^^^^^^^^^^^^^^^^^^^^^^^^^^^^^^^
  File "C:\Users\Umesh Patel\AppData\Local\Programs\Python\Python312\Lib\site-packages\pyscreeze\__init__.py", line 257, in _locateAll_opencv
    raise ImageNotFoundException('Could not locate the image (highest confidence = %.3f)' % result.max())
pyscreeze.ImageNotFoundException: Could not locate the image (highest confidence = 0.580)

During handling of the above exception, another exception occurred:

Traceback (most recent call last):
  File "c:\Users\Umesh Patel\Omnitrix\Stategy_Fibo copy.py", line 461, in <module>
    connection_check = pyautogui.locateOnScreen("Connnection.png", confidence=0.8)
                       ^^^^^^^^^^^^^^^^^^^^^^^^^^^^^^^^^^^^^^^^^^^^^^^^^^^^^^^^^^^
  File "C:\Users\Umesh Patel\AppData\Local\Programs\Python\Python312\Lib\site-packages\pyautogui\__init__.py", line 174, in wrapper
    raise ImageNotFoundException  # Raise PyAutoGUI's ImageNotFoundException.
    ^^^^^^^^^^^^^^^^^^^^^^^^^^^^
pyautogui.ImageNotFoundException
2024-10-05 03:25:43,361 - ERROR - Stategy_Fibo copy.py - 469 - An error occurred in the connection function: 
Traceback (most recent call last):
  File "C:\Users\Umesh Patel\AppData\Local\Programs\Python\Python312\Lib\site-packages\pyautogui\__init__.py", line 172, in wrapper
    return wrappedFunction(*args, **kwargs)
           ^^^^^^^^^^^^^^^^^^^^^^^^^^^^^^^^
  File "C:\Users\Umesh Patel\AppData\Local\Programs\Python\Python312\Lib\site-packages\pyautogui\__init__.py", line 210, in locateOnScreen
    return pyscreeze.locateOnScreen(*args, **kwargs)
           ^^^^^^^^^^^^^^^^^^^^^^^^^^^^^^^^^^^^^^^^^
  File "C:\Users\Umesh Patel\AppData\Local\Programs\Python\Python312\Lib\site-packages\pyscreeze\__init__.py", line 405, in locateOnScreen
    retVal = locate(image, screenshotIm, **kwargs)
             ^^^^^^^^^^^^^^^^^^^^^^^^^^^^^^^^^^^^^
  File "C:\Users\Umesh Patel\AppData\Local\Programs\Python\Python312\Lib\site-packages\pyscreeze\__init__.py", line 383, in locate
    points = tuple(locateAll(needleImage, haystackImage, **kwargs))
             ^^^^^^^^^^^^^^^^^^^^^^^^^^^^^^^^^^^^^^^^^^^^^^^^^^^^^^
  File "C:\Users\Umesh Patel\AppData\Local\Programs\Python\Python312\Lib\site-packages\pyscreeze\__init__.py", line 257, in _locateAll_opencv
    raise ImageNotFoundException('Could not locate the image (highest confidence = %.3f)' % result.max())
pyscreeze.ImageNotFoundException: Could not locate the image (highest confidence = 0.580)

During handling of the above exception, another exception occurred:

Traceback (most recent call last):
  File "c:\Users\Umesh Patel\Omnitrix\Stategy_Fibo copy.py", line 461, in <module>
    connection_check = pyautogui.locateOnScreen("Connnection.png", confidence=0.8)
                       ^^^^^^^^^^^^^^^^^^^^^^^^^^^^^^^^^^^^^^^^^^^^^^^^^^^^^^^^^^^
  File "C:\Users\Umesh Patel\AppData\Local\Programs\Python\Python312\Lib\site-packages\pyautogui\__init__.py", line 174, in wrapper
    raise ImageNotFoundException  # Raise PyAutoGUI's ImageNotFoundException.
    ^^^^^^^^^^^^^^^^^^^^^^^^^^^^
pyautogui.ImageNotFoundException
2024-10-05 03:25:46,086 - ERROR - Stategy_Fibo copy.py - 469 - An error occurred in the connection function: 
Traceback (most recent call last):
  File "C:\Users\Umesh Patel\AppData\Local\Programs\Python\Python312\Lib\site-packages\pyautogui\__init__.py", line 172, in wrapper
    return wrappedFunction(*args, **kwargs)
           ^^^^^^^^^^^^^^^^^^^^^^^^^^^^^^^^
  File "C:\Users\Umesh Patel\AppData\Local\Programs\Python\Python312\Lib\site-packages\pyautogui\__init__.py", line 210, in locateOnScreen
    return pyscreeze.locateOnScreen(*args, **kwargs)
           ^^^^^^^^^^^^^^^^^^^^^^^^^^^^^^^^^^^^^^^^^
  File "C:\Users\Umesh Patel\AppData\Local\Programs\Python\Python312\Lib\site-packages\pyscreeze\__init__.py", line 405, in locateOnScreen
    retVal = locate(image, screenshotIm, **kwargs)
             ^^^^^^^^^^^^^^^^^^^^^^^^^^^^^^^^^^^^^
  File "C:\Users\Umesh Patel\AppData\Local\Programs\Python\Python312\Lib\site-packages\pyscreeze\__init__.py", line 383, in locate
    points = tuple(locateAll(needleImage, haystackImage, **kwargs))
             ^^^^^^^^^^^^^^^^^^^^^^^^^^^^^^^^^^^^^^^^^^^^^^^^^^^^^^
  File "C:\Users\Umesh Patel\AppData\Local\Programs\Python\Python312\Lib\site-packages\pyscreeze\__init__.py", line 257, in _locateAll_opencv
    raise ImageNotFoundException('Could not locate the image (highest confidence = %.3f)' % result.max())
pyscreeze.ImageNotFoundException: Could not locate the image (highest confidence = 0.580)

During handling of the above exception, another exception occurred:

Traceback (most recent call last):
  File "c:\Users\Umesh Patel\Omnitrix\Stategy_Fibo copy.py", line 461, in <module>
    connection_check = pyautogui.locateOnScreen("Connnection.png", confidence=0.8)
                       ^^^^^^^^^^^^^^^^^^^^^^^^^^^^^^^^^^^^^^^^^^^^^^^^^^^^^^^^^^^
  File "C:\Users\Umesh Patel\AppData\Local\Programs\Python\Python312\Lib\site-packages\pyautogui\__init__.py", line 174, in wrapper
    raise ImageNotFoundException  # Raise PyAutoGUI's ImageNotFoundException.
    ^^^^^^^^^^^^^^^^^^^^^^^^^^^^
pyautogui.ImageNotFoundException
2024-10-05 03:25:48,791 - ERROR - Stategy_Fibo copy.py - 469 - An error occurred in the connection function: 
Traceback (most recent call last):
  File "C:\Users\Umesh Patel\AppData\Local\Programs\Python\Python312\Lib\site-packages\pyautogui\__init__.py", line 172, in wrapper
    return wrappedFunction(*args, **kwargs)
           ^^^^^^^^^^^^^^^^^^^^^^^^^^^^^^^^
  File "C:\Users\Umesh Patel\AppData\Local\Programs\Python\Python312\Lib\site-packages\pyautogui\__init__.py", line 210, in locateOnScreen
    return pyscreeze.locateOnScreen(*args, **kwargs)
           ^^^^^^^^^^^^^^^^^^^^^^^^^^^^^^^^^^^^^^^^^
  File "C:\Users\Umesh Patel\AppData\Local\Programs\Python\Python312\Lib\site-packages\pyscreeze\__init__.py", line 405, in locateOnScreen
    retVal = locate(image, screenshotIm, **kwargs)
             ^^^^^^^^^^^^^^^^^^^^^^^^^^^^^^^^^^^^^
  File "C:\Users\Umesh Patel\AppData\Local\Programs\Python\Python312\Lib\site-packages\pyscreeze\__init__.py", line 383, in locate
    points = tuple(locateAll(needleImage, haystackImage, **kwargs))
             ^^^^^^^^^^^^^^^^^^^^^^^^^^^^^^^^^^^^^^^^^^^^^^^^^^^^^^
  File "C:\Users\Umesh Patel\AppData\Local\Programs\Python\Python312\Lib\site-packages\pyscreeze\__init__.py", line 257, in _locateAll_opencv
    raise ImageNotFoundException('Could not locate the image (highest confidence = %.3f)' % result.max())
pyscreeze.ImageNotFoundException: Could not locate the image (highest confidence = 0.580)

During handling of the above exception, another exception occurred:

Traceback (most recent call last):
  File "c:\Users\Umesh Patel\Omnitrix\Stategy_Fibo copy.py", line 461, in <module>
    connection_check = pyautogui.locateOnScreen("Connnection.png", confidence=0.8)
                       ^^^^^^^^^^^^^^^^^^^^^^^^^^^^^^^^^^^^^^^^^^^^^^^^^^^^^^^^^^^
  File "C:\Users\Umesh Patel\AppData\Local\Programs\Python\Python312\Lib\site-packages\pyautogui\__init__.py", line 174, in wrapper
    raise ImageNotFoundException  # Raise PyAutoGUI's ImageNotFoundException.
    ^^^^^^^^^^^^^^^^^^^^^^^^^^^^
pyautogui.ImageNotFoundException
2024-10-05 03:25:52,366 - ERROR - Stategy_Fibo copy.py - 806 - An error occurred during the betting process: name 'lenBet' is not defined
Traceback (most recent call last):
  File "c:\Users\Umesh Patel\Omnitrix\Stategy_Fibo copy.py", line 770, in <module>
    if(Bethistory[lenBet-2]=='A'and Bethistory[lenBet-1]=='A'):
                  ^^^^^^
NameError: name 'lenBet' is not defined
2024-10-05 03:25:54,999 - ERROR - Stategy_Fibo copy.py - 469 - An error occurred in the connection function: 
Traceback (most recent call last):
  File "C:\Users\Umesh Patel\AppData\Local\Programs\Python\Python312\Lib\site-packages\pyautogui\__init__.py", line 172, in wrapper
    return wrappedFunction(*args, **kwargs)
           ^^^^^^^^^^^^^^^^^^^^^^^^^^^^^^^^
  File "C:\Users\Umesh Patel\AppData\Local\Programs\Python\Python312\Lib\site-packages\pyautogui\__init__.py", line 210, in locateOnScreen
    return pyscreeze.locateOnScreen(*args, **kwargs)
           ^^^^^^^^^^^^^^^^^^^^^^^^^^^^^^^^^^^^^^^^^
  File "C:\Users\Umesh Patel\AppData\Local\Programs\Python\Python312\Lib\site-packages\pyscreeze\__init__.py", line 405, in locateOnScreen
    retVal = locate(image, screenshotIm, **kwargs)
             ^^^^^^^^^^^^^^^^^^^^^^^^^^^^^^^^^^^^^
  File "C:\Users\Umesh Patel\AppData\Local\Programs\Python\Python312\Lib\site-packages\pyscreeze\__init__.py", line 383, in locate
    points = tuple(locateAll(needleImage, haystackImage, **kwargs))
             ^^^^^^^^^^^^^^^^^^^^^^^^^^^^^^^^^^^^^^^^^^^^^^^^^^^^^^
  File "C:\Users\Umesh Patel\AppData\Local\Programs\Python\Python312\Lib\site-packages\pyscreeze\__init__.py", line 257, in _locateAll_opencv
    raise ImageNotFoundException('Could not locate the image (highest confidence = %.3f)' % result.max())
pyscreeze.ImageNotFoundException: Could not locate the image (highest confidence = 0.580)

During handling of the above exception, another exception occurred:

Traceback (most recent call last):
  File "c:\Users\Umesh Patel\Omnitrix\Stategy_Fibo copy.py", line 461, in <module>
    connection_check = pyautogui.locateOnScreen("Connnection.png", confidence=0.8)
                       ^^^^^^^^^^^^^^^^^^^^^^^^^^^^^^^^^^^^^^^^^^^^^^^^^^^^^^^^^^^
  File "C:\Users\Umesh Patel\AppData\Local\Programs\Python\Python312\Lib\site-packages\pyautogui\__init__.py", line 174, in wrapper
    raise ImageNotFoundException  # Raise PyAutoGUI's ImageNotFoundException.
    ^^^^^^^^^^^^^^^^^^^^^^^^^^^^
pyautogui.ImageNotFoundException
2024-10-05 03:25:58,562 - ERROR - Stategy_Fibo copy.py - 806 - An error occurred during the betting process: name 'lenBet' is not defined
Traceback (most recent call last):
  File "c:\Users\Umesh Patel\Omnitrix\Stategy_Fibo copy.py", line 770, in <module>
    if(Bethistory[lenBet-2]=='A'and Bethistory[lenBet-1]=='A'):
                  ^^^^^^
NameError: name 'lenBet' is not defined
